2020-05-10 04:09:51,072 - __main__ - ERROR - time data '2020-03-31 18:03:03' does not match format '%d-%m-%y %H:%M'
Traceback (most recent call last):
  File "/Users/qiutingli/Projects/monitoring-athletes-performance/main/data_summary.py", line 41, in summarize_dates
    dates = [datetime.datetime.strptime(date, "%d-%m-%y %H:%M") for date in df['Date']]
  File "/Users/qiutingli/Projects/monitoring-athletes-performance/main/data_summary.py", line 41, in <listcomp>
    dates = [datetime.datetime.strptime(date, "%d-%m-%y %H:%M") for date in df['Date']]
  File "/Users/qiutingli/anaconda3/lib/python3.6/_strptime.py", line 565, in _strptime_datetime
    tt, fraction = _strptime(data_string, format)
  File "/Users/qiutingli/anaconda3/lib/python3.6/_strptime.py", line 362, in _strptime
    (data_string, format))
ValueError: time data '2020-03-31 18:03:03' does not match format '%d-%m-%y %H:%M'
2020-05-10 04:09:51,086 - __main__ - ERROR - time data '2020-03-04 05:45:03' does not match format '%d-%m-%y %H:%M'
Traceback (most recent call last):
  File "/Users/qiutingli/Projects/monitoring-athletes-performance/main/data_summary.py", line 41, in summarize_dates
    dates = [datetime.datetime.strptime(date, "%d-%m-%y %H:%M") for date in df['Date']]
  File "/Users/qiutingli/Projects/monitoring-athletes-performance/main/data_summary.py", line 41, in <listcomp>
    dates = [datetime.datetime.strptime(date, "%d-%m-%y %H:%M") for date in df['Date']]
  File "/Users/qiutingli/anaconda3/lib/python3.6/_strptime.py", line 565, in _strptime_datetime
    tt, fraction = _strptime(data_string, format)
  File "/Users/qiutingli/anaconda3/lib/python3.6/_strptime.py", line 362, in _strptime
    (data_string, format))
ValueError: time data '2020-03-04 05:45:03' does not match format '%d-%m-%y %H:%M'
2020-05-10 04:09:51,092 - __main__ - ERROR - time data '2020-02-22 07:30:13' does not match format '%d-%m-%y %H:%M'
Traceback (most recent call last):
  File "/Users/qiutingli/Projects/monitoring-athletes-performance/main/data_summary.py", line 41, in summarize_dates
    dates = [datetime.datetime.strptime(date, "%d-%m-%y %H:%M") for date in df['Date']]
  File "/Users/qiutingli/Projects/monitoring-athletes-performance/main/data_summary.py", line 41, in <listcomp>
    dates = [datetime.datetime.strptime(date, "%d-%m-%y %H:%M") for date in df['Date']]
  File "/Users/qiutingli/anaconda3/lib/python3.6/_strptime.py", line 565, in _strptime_datetime
    tt, fraction = _strptime(data_string, format)
  File "/Users/qiutingli/anaconda3/lib/python3.6/_strptime.py", line 362, in _strptime
    (data_string, format))
ValueError: time data '2020-02-22 07:30:13' does not match format '%d-%m-%y %H:%M'
2020-05-10 04:09:51,100 - __main__ - ERROR - time data '2020-03-24 17:21:40' does not match format '%d-%m-%y %H:%M'
Traceback (most recent call last):
  File "/Users/qiutingli/Projects/monitoring-athletes-performance/main/data_summary.py", line 41, in summarize_dates
    dates = [datetime.datetime.strptime(date, "%d-%m-%y %H:%M") for date in df['Date']]
  File "/Users/qiutingli/Projects/monitoring-athletes-performance/main/data_summary.py", line 41, in <listcomp>
    dates = [datetime.datetime.strptime(date, "%d-%m-%y %H:%M") for date in df['Date']]
  File "/Users/qiutingli/anaconda3/lib/python3.6/_strptime.py", line 565, in _strptime_datetime
    tt, fraction = _strptime(data_string, format)
  File "/Users/qiutingli/anaconda3/lib/python3.6/_strptime.py", line 362, in _strptime
    (data_string, format))
ValueError: time data '2020-03-24 17:21:40' does not match format '%d-%m-%y %H:%M'
2020-05-10 04:09:51,303 - __main__ - ERROR - time data '2020-03-31 18:03:03' does not match format '%d-%m-%y %H:%M'
Traceback (most recent call last):
  File "/Users/qiutingli/Projects/monitoring-athletes-performance/main/data_summary.py", line 41, in summarize_dates
    dates = [datetime.datetime.strptime(date, "%d-%m-%y %H:%M") for date in df['Date']]
  File "/Users/qiutingli/Projects/monitoring-athletes-performance/main/data_summary.py", line 41, in <listcomp>
    dates = [datetime.datetime.strptime(date, "%d-%m-%y %H:%M") for date in df['Date']]
  File "/Users/qiutingli/anaconda3/lib/python3.6/_strptime.py", line 565, in _strptime_datetime
    tt, fraction = _strptime(data_string, format)
  File "/Users/qiutingli/anaconda3/lib/python3.6/_strptime.py", line 362, in _strptime
    (data_string, format))
ValueError: time data '2020-03-31 18:03:03' does not match format '%d-%m-%y %H:%M'
2020-05-10 04:09:51,311 - __main__ - ERROR - time data '2020-03-04 05:45:03' does not match format '%d-%m-%y %H:%M'
Traceback (most recent call last):
  File "/Users/qiutingli/Projects/monitoring-athletes-performance/main/data_summary.py", line 41, in summarize_dates
    dates = [datetime.datetime.strptime(date, "%d-%m-%y %H:%M") for date in df['Date']]
  File "/Users/qiutingli/Projects/monitoring-athletes-performance/main/data_summary.py", line 41, in <listcomp>
    dates = [datetime.datetime.strptime(date, "%d-%m-%y %H:%M") for date in df['Date']]
  File "/Users/qiutingli/anaconda3/lib/python3.6/_strptime.py", line 565, in _strptime_datetime
    tt, fraction = _strptime(data_string, format)
  File "/Users/qiutingli/anaconda3/lib/python3.6/_strptime.py", line 362, in _strptime
    (data_string, format))
ValueError: time data '2020-03-04 05:45:03' does not match format '%d-%m-%y %H:%M'
2020-05-10 04:09:51,316 - __main__ - ERROR - time data '2020-02-22 07:30:13' does not match format '%d-%m-%y %H:%M'
Traceback (most recent call last):
  File "/Users/qiutingli/Projects/monitoring-athletes-performance/main/data_summary.py", line 41, in summarize_dates
    dates = [datetime.datetime.strptime(date, "%d-%m-%y %H:%M") for date in df['Date']]
  File "/Users/qiutingli/Projects/monitoring-athletes-performance/main/data_summary.py", line 41, in <listcomp>
    dates = [datetime.datetime.strptime(date, "%d-%m-%y %H:%M") for date in df['Date']]
  File "/Users/qiutingli/anaconda3/lib/python3.6/_strptime.py", line 565, in _strptime_datetime
    tt, fraction = _strptime(data_string, format)
  File "/Users/qiutingli/anaconda3/lib/python3.6/_strptime.py", line 362, in _strptime
    (data_string, format))
ValueError: time data '2020-02-22 07:30:13' does not match format '%d-%m-%y %H:%M'
2020-05-10 04:09:51,322 - __main__ - ERROR - time data '2020-03-24 17:21:40' does not match format '%d-%m-%y %H:%M'
Traceback (most recent call last):
  File "/Users/qiutingli/Projects/monitoring-athletes-performance/main/data_summary.py", line 41, in summarize_dates
    dates = [datetime.datetime.strptime(date, "%d-%m-%y %H:%M") for date in df['Date']]
  File "/Users/qiutingli/Projects/monitoring-athletes-performance/main/data_summary.py", line 41, in <listcomp>
    dates = [datetime.datetime.strptime(date, "%d-%m-%y %H:%M") for date in df['Date']]
  File "/Users/qiutingli/anaconda3/lib/python3.6/_strptime.py", line 565, in _strptime_datetime
    tt, fraction = _strptime(data_string, format)
  File "/Users/qiutingli/anaconda3/lib/python3.6/_strptime.py", line 362, in _strptime
    (data_string, format))
ValueError: time data '2020-03-24 17:21:40' does not match format '%d-%m-%y %H:%M'
2020-05-10 04:09:51,444 - __main__ - ERROR - time data '17/03/2020 6:07' does not match format '%d-%m-%y %H:%M'
Traceback (most recent call last):
  File "/Users/qiutingli/Projects/monitoring-athletes-performance/main/data_summary.py", line 41, in summarize_dates
    dates = [datetime.datetime.strptime(date, "%d-%m-%y %H:%M") for date in df['Date']]
  File "/Users/qiutingli/Projects/monitoring-athletes-performance/main/data_summary.py", line 41, in <listcomp>
    dates = [datetime.datetime.strptime(date, "%d-%m-%y %H:%M") for date in df['Date']]
  File "/Users/qiutingli/anaconda3/lib/python3.6/_strptime.py", line 565, in _strptime_datetime
    tt, fraction = _strptime(data_string, format)
  File "/Users/qiutingli/anaconda3/lib/python3.6/_strptime.py", line 362, in _strptime
    (data_string, format))
ValueError: time data '17/03/2020 6:07' does not match format '%d-%m-%y %H:%M'
2020-05-10 04:09:51,449 - __main__ - ERROR - 'Avg Speed'
Traceback (most recent call last):
  File "/Users/qiutingli/anaconda3/lib/python3.6/site-packages/pandas/core/indexes/base.py", line 3063, in get_loc
    return self._engine.get_loc(key)
  File "pandas/_libs/index.pyx", line 140, in pandas._libs.index.IndexEngine.get_loc
  File "pandas/_libs/index.pyx", line 162, in pandas._libs.index.IndexEngine.get_loc
  File "pandas/_libs/hashtable_class_helper.pxi", line 1492, in pandas._libs.hashtable.PyObjectHashTable.get_item
  File "pandas/_libs/hashtable_class_helper.pxi", line 1500, in pandas._libs.hashtable.PyObjectHashTable.get_item
KeyError: 'Avg Speed'

During handling of the above exception, another exception occurred:

Traceback (most recent call last):
  File "/Users/qiutingli/Projects/monitoring-athletes-performance/main/data_summary.py", line 83, in summarize_features
    feature_values = [float(str(var).replace(',', '')) for var in df[feature] if re.match(r'^-?\d+(?:\.\d+)?$', str(var)) is not None]
  File "/Users/qiutingli/anaconda3/lib/python3.6/site-packages/pandas/core/frame.py", line 2685, in __getitem__
    return self._getitem_column(key)
  File "/Users/qiutingli/anaconda3/lib/python3.6/site-packages/pandas/core/frame.py", line 2692, in _getitem_column
    return self._get_item_cache(key)
  File "/Users/qiutingli/anaconda3/lib/python3.6/site-packages/pandas/core/generic.py", line 2486, in _get_item_cache
    values = self._data.get(item)
  File "/Users/qiutingli/anaconda3/lib/python3.6/site-packages/pandas/core/internals.py", line 4115, in get
    loc = self.items.get_loc(item)
  File "/Users/qiutingli/anaconda3/lib/python3.6/site-packages/pandas/core/indexes/base.py", line 3065, in get_loc
    return self._engine.get_loc(self._maybe_cast_indexer(key))
  File "pandas/_libs/index.pyx", line 140, in pandas._libs.index.IndexEngine.get_loc
  File "pandas/_libs/index.pyx", line 162, in pandas._libs.index.IndexEngine.get_loc
  File "pandas/_libs/hashtable_class_helper.pxi", line 1492, in pandas._libs.hashtable.PyObjectHashTable.get_item
  File "pandas/_libs/hashtable_class_helper.pxi", line 1500, in pandas._libs.hashtable.PyObjectHashTable.get_item
KeyError: 'Avg Speed'
2020-05-10 04:09:51,469 - __main__ - ERROR - time data '4/03/2020 5:47' does not match format '%d-%m-%y %H:%M'
Traceback (most recent call last):
  File "/Users/qiutingli/Projects/monitoring-athletes-performance/main/data_summary.py", line 41, in summarize_dates
    dates = [datetime.datetime.strptime(date, "%d-%m-%y %H:%M") for date in df['Date']]
  File "/Users/qiutingli/Projects/monitoring-athletes-performance/main/data_summary.py", line 41, in <listcomp>
    dates = [datetime.datetime.strptime(date, "%d-%m-%y %H:%M") for date in df['Date']]
  File "/Users/qiutingli/anaconda3/lib/python3.6/_strptime.py", line 565, in _strptime_datetime
    tt, fraction = _strptime(data_string, format)
  File "/Users/qiutingli/anaconda3/lib/python3.6/_strptime.py", line 362, in _strptime
    (data_string, format))
ValueError: time data '4/03/2020 5:47' does not match format '%d-%m-%y %H:%M'
2020-05-10 04:09:51,474 - __main__ - ERROR - 'Avg Speed'
Traceback (most recent call last):
  File "/Users/qiutingli/anaconda3/lib/python3.6/site-packages/pandas/core/indexes/base.py", line 3063, in get_loc
    return self._engine.get_loc(key)
  File "pandas/_libs/index.pyx", line 140, in pandas._libs.index.IndexEngine.get_loc
  File "pandas/_libs/index.pyx", line 162, in pandas._libs.index.IndexEngine.get_loc
  File "pandas/_libs/hashtable_class_helper.pxi", line 1492, in pandas._libs.hashtable.PyObjectHashTable.get_item
  File "pandas/_libs/hashtable_class_helper.pxi", line 1500, in pandas._libs.hashtable.PyObjectHashTable.get_item
KeyError: 'Avg Speed'

During handling of the above exception, another exception occurred:

Traceback (most recent call last):
  File "/Users/qiutingli/Projects/monitoring-athletes-performance/main/data_summary.py", line 83, in summarize_features
    feature_values = [float(str(var).replace(',', '')) for var in df[feature] if re.match(r'^-?\d+(?:\.\d+)?$', str(var)) is not None]
  File "/Users/qiutingli/anaconda3/lib/python3.6/site-packages/pandas/core/frame.py", line 2685, in __getitem__
    return self._getitem_column(key)
  File "/Users/qiutingli/anaconda3/lib/python3.6/site-packages/pandas/core/frame.py", line 2692, in _getitem_column
    return self._get_item_cache(key)
  File "/Users/qiutingli/anaconda3/lib/python3.6/site-packages/pandas/core/generic.py", line 2486, in _get_item_cache
    values = self._data.get(item)
  File "/Users/qiutingli/anaconda3/lib/python3.6/site-packages/pandas/core/internals.py", line 4115, in get
    loc = self.items.get_loc(item)
  File "/Users/qiutingli/anaconda3/lib/python3.6/site-packages/pandas/core/indexes/base.py", line 3065, in get_loc
    return self._engine.get_loc(self._maybe_cast_indexer(key))
  File "pandas/_libs/index.pyx", line 140, in pandas._libs.index.IndexEngine.get_loc
  File "pandas/_libs/index.pyx", line 162, in pandas._libs.index.IndexEngine.get_loc
  File "pandas/_libs/hashtable_class_helper.pxi", line 1492, in pandas._libs.hashtable.PyObjectHashTable.get_item
  File "pandas/_libs/hashtable_class_helper.pxi", line 1500, in pandas._libs.hashtable.PyObjectHashTable.get_item
KeyError: 'Avg Speed'
2020-05-10 04:09:51,476 - __main__ - ERROR - time data '14/09/2019 13:57' does not match format '%d-%m-%y %H:%M'
Traceback (most recent call last):
  File "/Users/qiutingli/Projects/monitoring-athletes-performance/main/data_summary.py", line 41, in summarize_dates
    dates = [datetime.datetime.strptime(date, "%d-%m-%y %H:%M") for date in df['Date']]
  File "/Users/qiutingli/Projects/monitoring-athletes-performance/main/data_summary.py", line 41, in <listcomp>
    dates = [datetime.datetime.strptime(date, "%d-%m-%y %H:%M") for date in df['Date']]
  File "/Users/qiutingli/anaconda3/lib/python3.6/_strptime.py", line 565, in _strptime_datetime
    tt, fraction = _strptime(data_string, format)
  File "/Users/qiutingli/anaconda3/lib/python3.6/_strptime.py", line 362, in _strptime
    (data_string, format))
ValueError: time data '14/09/2019 13:57' does not match format '%d-%m-%y %H:%M'
2020-05-10 04:09:51,480 - __main__ - ERROR - 'Avg Speed'
Traceback (most recent call last):
  File "/Users/qiutingli/anaconda3/lib/python3.6/site-packages/pandas/core/indexes/base.py", line 3063, in get_loc
    return self._engine.get_loc(key)
  File "pandas/_libs/index.pyx", line 140, in pandas._libs.index.IndexEngine.get_loc
  File "pandas/_libs/index.pyx", line 162, in pandas._libs.index.IndexEngine.get_loc
  File "pandas/_libs/hashtable_class_helper.pxi", line 1492, in pandas._libs.hashtable.PyObjectHashTable.get_item
  File "pandas/_libs/hashtable_class_helper.pxi", line 1500, in pandas._libs.hashtable.PyObjectHashTable.get_item
KeyError: 'Avg Speed'

During handling of the above exception, another exception occurred:

Traceback (most recent call last):
  File "/Users/qiutingli/Projects/monitoring-athletes-performance/main/data_summary.py", line 83, in summarize_features
    feature_values = [float(str(var).replace(',', '')) for var in df[feature] if re.match(r'^-?\d+(?:\.\d+)?$', str(var)) is not None]
  File "/Users/qiutingli/anaconda3/lib/python3.6/site-packages/pandas/core/frame.py", line 2685, in __getitem__
    return self._getitem_column(key)
  File "/Users/qiutingli/anaconda3/lib/python3.6/site-packages/pandas/core/frame.py", line 2692, in _getitem_column
    return self._get_item_cache(key)
  File "/Users/qiutingli/anaconda3/lib/python3.6/site-packages/pandas/core/generic.py", line 2486, in _get_item_cache
    values = self._data.get(item)
  File "/Users/qiutingli/anaconda3/lib/python3.6/site-packages/pandas/core/internals.py", line 4115, in get
    loc = self.items.get_loc(item)
  File "/Users/qiutingli/anaconda3/lib/python3.6/site-packages/pandas/core/indexes/base.py", line 3065, in get_loc
    return self._engine.get_loc(self._maybe_cast_indexer(key))
  File "pandas/_libs/index.pyx", line 140, in pandas._libs.index.IndexEngine.get_loc
  File "pandas/_libs/index.pyx", line 162, in pandas._libs.index.IndexEngine.get_loc
  File "pandas/_libs/hashtable_class_helper.pxi", line 1492, in pandas._libs.hashtable.PyObjectHashTable.get_item
  File "pandas/_libs/hashtable_class_helper.pxi", line 1500, in pandas._libs.hashtable.PyObjectHashTable.get_item
KeyError: 'Avg Speed'
2020-05-10 04:09:51,482 - __main__ - ERROR - time data '28/03/2020 8:17' does not match format '%d-%m-%y %H:%M'
Traceback (most recent call last):
  File "/Users/qiutingli/Projects/monitoring-athletes-performance/main/data_summary.py", line 41, in summarize_dates
    dates = [datetime.datetime.strptime(date, "%d-%m-%y %H:%M") for date in df['Date']]
  File "/Users/qiutingli/Projects/monitoring-athletes-performance/main/data_summary.py", line 41, in <listcomp>
    dates = [datetime.datetime.strptime(date, "%d-%m-%y %H:%M") for date in df['Date']]
  File "/Users/qiutingli/anaconda3/lib/python3.6/_strptime.py", line 565, in _strptime_datetime
    tt, fraction = _strptime(data_string, format)
  File "/Users/qiutingli/anaconda3/lib/python3.6/_strptime.py", line 362, in _strptime
    (data_string, format))
ValueError: time data '28/03/2020 8:17' does not match format '%d-%m-%y %H:%M'
2020-05-10 04:09:51,485 - __main__ - ERROR - 'Avg Speed'
Traceback (most recent call last):
  File "/Users/qiutingli/anaconda3/lib/python3.6/site-packages/pandas/core/indexes/base.py", line 3063, in get_loc
    return self._engine.get_loc(key)
  File "pandas/_libs/index.pyx", line 140, in pandas._libs.index.IndexEngine.get_loc
  File "pandas/_libs/index.pyx", line 162, in pandas._libs.index.IndexEngine.get_loc
  File "pandas/_libs/hashtable_class_helper.pxi", line 1492, in pandas._libs.hashtable.PyObjectHashTable.get_item
  File "pandas/_libs/hashtable_class_helper.pxi", line 1500, in pandas._libs.hashtable.PyObjectHashTable.get_item
KeyError: 'Avg Speed'

During handling of the above exception, another exception occurred:

Traceback (most recent call last):
  File "/Users/qiutingli/Projects/monitoring-athletes-performance/main/data_summary.py", line 83, in summarize_features
    feature_values = [float(str(var).replace(',', '')) for var in df[feature] if re.match(r'^-?\d+(?:\.\d+)?$', str(var)) is not None]
  File "/Users/qiutingli/anaconda3/lib/python3.6/site-packages/pandas/core/frame.py", line 2685, in __getitem__
    return self._getitem_column(key)
  File "/Users/qiutingli/anaconda3/lib/python3.6/site-packages/pandas/core/frame.py", line 2692, in _getitem_column
    return self._get_item_cache(key)
  File "/Users/qiutingli/anaconda3/lib/python3.6/site-packages/pandas/core/generic.py", line 2486, in _get_item_cache
    values = self._data.get(item)
  File "/Users/qiutingli/anaconda3/lib/python3.6/site-packages/pandas/core/internals.py", line 4115, in get
    loc = self.items.get_loc(item)
  File "/Users/qiutingli/anaconda3/lib/python3.6/site-packages/pandas/core/indexes/base.py", line 3065, in get_loc
    return self._engine.get_loc(self._maybe_cast_indexer(key))
  File "pandas/_libs/index.pyx", line 140, in pandas._libs.index.IndexEngine.get_loc
  File "pandas/_libs/index.pyx", line 162, in pandas._libs.index.IndexEngine.get_loc
  File "pandas/_libs/hashtable_class_helper.pxi", line 1492, in pandas._libs.hashtable.PyObjectHashTable.get_item
  File "pandas/_libs/hashtable_class_helper.pxi", line 1500, in pandas._libs.hashtable.PyObjectHashTable.get_item
KeyError: 'Avg Speed'
2020-05-10 04:09:51,560 - __main__ - ERROR - time data '2020-04-12 08:57:05' does not match format '%d-%m-%y %H:%M'
Traceback (most recent call last):
  File "/Users/qiutingli/Projects/monitoring-athletes-performance/main/data_summary.py", line 41, in summarize_dates
    dates = [datetime.datetime.strptime(date, "%d-%m-%y %H:%M") for date in df['Date']]
  File "/Users/qiutingli/Projects/monitoring-athletes-performance/main/data_summary.py", line 41, in <listcomp>
    dates = [datetime.datetime.strptime(date, "%d-%m-%y %H:%M") for date in df['Date']]
  File "/Users/qiutingli/anaconda3/lib/python3.6/_strptime.py", line 565, in _strptime_datetime
    tt, fraction = _strptime(data_string, format)
  File "/Users/qiutingli/anaconda3/lib/python3.6/_strptime.py", line 362, in _strptime
    (data_string, format))
ValueError: time data '2020-04-12 08:57:05' does not match format '%d-%m-%y %H:%M'
2020-05-10 04:09:51,562 - __main__ - ERROR - could not convert string to float: '14,8'
Traceback (most recent call last):
  File "/Users/qiutingli/Projects/monitoring-athletes-performance/main/data_summary.py", line 56, in summarize_workout_time
    total_seconds = total_seconds*60 + float(t)
ValueError: could not convert string to float: '14,8'
2020-05-10 04:09:51,566 - __main__ - ERROR - 'Avg Power'
Traceback (most recent call last):
  File "/Users/qiutingli/anaconda3/lib/python3.6/site-packages/pandas/core/indexes/base.py", line 3063, in get_loc
    return self._engine.get_loc(key)
  File "pandas/_libs/index.pyx", line 140, in pandas._libs.index.IndexEngine.get_loc
  File "pandas/_libs/index.pyx", line 162, in pandas._libs.index.IndexEngine.get_loc
  File "pandas/_libs/hashtable_class_helper.pxi", line 1492, in pandas._libs.hashtable.PyObjectHashTable.get_item
  File "pandas/_libs/hashtable_class_helper.pxi", line 1500, in pandas._libs.hashtable.PyObjectHashTable.get_item
KeyError: 'Avg Power'

During handling of the above exception, another exception occurred:

Traceback (most recent call last):
  File "/Users/qiutingli/Projects/monitoring-athletes-performance/main/data_summary.py", line 83, in summarize_features
    feature_values = [float(str(var).replace(',', '')) for var in df[feature] if re.match(r'^-?\d+(?:\.\d+)?$', str(var)) is not None]
  File "/Users/qiutingli/anaconda3/lib/python3.6/site-packages/pandas/core/frame.py", line 2685, in __getitem__
    return self._getitem_column(key)
  File "/Users/qiutingli/anaconda3/lib/python3.6/site-packages/pandas/core/frame.py", line 2692, in _getitem_column
    return self._get_item_cache(key)
  File "/Users/qiutingli/anaconda3/lib/python3.6/site-packages/pandas/core/generic.py", line 2486, in _get_item_cache
    values = self._data.get(item)
  File "/Users/qiutingli/anaconda3/lib/python3.6/site-packages/pandas/core/internals.py", line 4115, in get
    loc = self.items.get_loc(item)
  File "/Users/qiutingli/anaconda3/lib/python3.6/site-packages/pandas/core/indexes/base.py", line 3065, in get_loc
    return self._engine.get_loc(self._maybe_cast_indexer(key))
  File "pandas/_libs/index.pyx", line 140, in pandas._libs.index.IndexEngine.get_loc
  File "pandas/_libs/index.pyx", line 162, in pandas._libs.index.IndexEngine.get_loc
  File "pandas/_libs/hashtable_class_helper.pxi", line 1492, in pandas._libs.hashtable.PyObjectHashTable.get_item
  File "pandas/_libs/hashtable_class_helper.pxi", line 1500, in pandas._libs.hashtable.PyObjectHashTable.get_item
KeyError: 'Avg Power'
2020-05-10 04:09:51,567 - __main__ - ERROR - time data '2020-03-18 05:48:13' does not match format '%d-%m-%y %H:%M'
Traceback (most recent call last):
  File "/Users/qiutingli/Projects/monitoring-athletes-performance/main/data_summary.py", line 41, in summarize_dates
    dates = [datetime.datetime.strptime(date, "%d-%m-%y %H:%M") for date in df['Date']]
  File "/Users/qiutingli/Projects/monitoring-athletes-performance/main/data_summary.py", line 41, in <listcomp>
    dates = [datetime.datetime.strptime(date, "%d-%m-%y %H:%M") for date in df['Date']]
  File "/Users/qiutingli/anaconda3/lib/python3.6/_strptime.py", line 565, in _strptime_datetime
    tt, fraction = _strptime(data_string, format)
  File "/Users/qiutingli/anaconda3/lib/python3.6/_strptime.py", line 362, in _strptime
    (data_string, format))
ValueError: time data '2020-03-18 05:48:13' does not match format '%d-%m-%y %H:%M'
2020-05-10 04:09:51,568 - __main__ - ERROR - could not convert string to float: '15,1'
Traceback (most recent call last):
  File "/Users/qiutingli/Projects/monitoring-athletes-performance/main/data_summary.py", line 56, in summarize_workout_time
    total_seconds = total_seconds*60 + float(t)
ValueError: could not convert string to float: '15,1'
2020-05-10 04:09:51,571 - __main__ - ERROR - 'Avg Power'
Traceback (most recent call last):
  File "/Users/qiutingli/anaconda3/lib/python3.6/site-packages/pandas/core/indexes/base.py", line 3063, in get_loc
    return self._engine.get_loc(key)
  File "pandas/_libs/index.pyx", line 140, in pandas._libs.index.IndexEngine.get_loc
  File "pandas/_libs/index.pyx", line 162, in pandas._libs.index.IndexEngine.get_loc
  File "pandas/_libs/hashtable_class_helper.pxi", line 1492, in pandas._libs.hashtable.PyObjectHashTable.get_item
  File "pandas/_libs/hashtable_class_helper.pxi", line 1500, in pandas._libs.hashtable.PyObjectHashTable.get_item
KeyError: 'Avg Power'

During handling of the above exception, another exception occurred:

Traceback (most recent call last):
  File "/Users/qiutingli/Projects/monitoring-athletes-performance/main/data_summary.py", line 83, in summarize_features
    feature_values = [float(str(var).replace(',', '')) for var in df[feature] if re.match(r'^-?\d+(?:\.\d+)?$', str(var)) is not None]
  File "/Users/qiutingli/anaconda3/lib/python3.6/site-packages/pandas/core/frame.py", line 2685, in __getitem__
    return self._getitem_column(key)
  File "/Users/qiutingli/anaconda3/lib/python3.6/site-packages/pandas/core/frame.py", line 2692, in _getitem_column
    return self._get_item_cache(key)
  File "/Users/qiutingli/anaconda3/lib/python3.6/site-packages/pandas/core/generic.py", line 2486, in _get_item_cache
    values = self._data.get(item)
  File "/Users/qiutingli/anaconda3/lib/python3.6/site-packages/pandas/core/internals.py", line 4115, in get
    loc = self.items.get_loc(item)
  File "/Users/qiutingli/anaconda3/lib/python3.6/site-packages/pandas/core/indexes/base.py", line 3065, in get_loc
    return self._engine.get_loc(self._maybe_cast_indexer(key))
  File "pandas/_libs/index.pyx", line 140, in pandas._libs.index.IndexEngine.get_loc
  File "pandas/_libs/index.pyx", line 162, in pandas._libs.index.IndexEngine.get_loc
  File "pandas/_libs/hashtable_class_helper.pxi", line 1492, in pandas._libs.hashtable.PyObjectHashTable.get_item
  File "pandas/_libs/hashtable_class_helper.pxi", line 1500, in pandas._libs.hashtable.PyObjectHashTable.get_item
KeyError: 'Avg Power'
2020-05-10 04:09:51,572 - __main__ - ERROR - time data '2020-04-12 16:43:49' does not match format '%d-%m-%y %H:%M'
Traceback (most recent call last):
  File "/Users/qiutingli/Projects/monitoring-athletes-performance/main/data_summary.py", line 41, in summarize_dates
    dates = [datetime.datetime.strptime(date, "%d-%m-%y %H:%M") for date in df['Date']]
  File "/Users/qiutingli/Projects/monitoring-athletes-performance/main/data_summary.py", line 41, in <listcomp>
    dates = [datetime.datetime.strptime(date, "%d-%m-%y %H:%M") for date in df['Date']]
  File "/Users/qiutingli/anaconda3/lib/python3.6/_strptime.py", line 565, in _strptime_datetime
    tt, fraction = _strptime(data_string, format)
  File "/Users/qiutingli/anaconda3/lib/python3.6/_strptime.py", line 362, in _strptime
    (data_string, format))
ValueError: time data '2020-04-12 16:43:49' does not match format '%d-%m-%y %H:%M'
2020-05-10 04:09:51,573 - __main__ - ERROR - could not convert string to float: '14,1'
Traceback (most recent call last):
  File "/Users/qiutingli/Projects/monitoring-athletes-performance/main/data_summary.py", line 56, in summarize_workout_time
    total_seconds = total_seconds*60 + float(t)
ValueError: could not convert string to float: '14,1'
2020-05-10 04:09:51,575 - __main__ - ERROR - 'Avg Power'
Traceback (most recent call last):
  File "/Users/qiutingli/anaconda3/lib/python3.6/site-packages/pandas/core/indexes/base.py", line 3063, in get_loc
    return self._engine.get_loc(key)
  File "pandas/_libs/index.pyx", line 140, in pandas._libs.index.IndexEngine.get_loc
  File "pandas/_libs/index.pyx", line 162, in pandas._libs.index.IndexEngine.get_loc
  File "pandas/_libs/hashtable_class_helper.pxi", line 1492, in pandas._libs.hashtable.PyObjectHashTable.get_item
  File "pandas/_libs/hashtable_class_helper.pxi", line 1500, in pandas._libs.hashtable.PyObjectHashTable.get_item
KeyError: 'Avg Power'

During handling of the above exception, another exception occurred:

Traceback (most recent call last):
  File "/Users/qiutingli/Projects/monitoring-athletes-performance/main/data_summary.py", line 83, in summarize_features
    feature_values = [float(str(var).replace(',', '')) for var in df[feature] if re.match(r'^-?\d+(?:\.\d+)?$', str(var)) is not None]
  File "/Users/qiutingli/anaconda3/lib/python3.6/site-packages/pandas/core/frame.py", line 2685, in __getitem__
    return self._getitem_column(key)
  File "/Users/qiutingli/anaconda3/lib/python3.6/site-packages/pandas/core/frame.py", line 2692, in _getitem_column
    return self._get_item_cache(key)
  File "/Users/qiutingli/anaconda3/lib/python3.6/site-packages/pandas/core/generic.py", line 2486, in _get_item_cache
    values = self._data.get(item)
  File "/Users/qiutingli/anaconda3/lib/python3.6/site-packages/pandas/core/internals.py", line 4115, in get
    loc = self.items.get_loc(item)
  File "/Users/qiutingli/anaconda3/lib/python3.6/site-packages/pandas/core/indexes/base.py", line 3065, in get_loc
    return self._engine.get_loc(self._maybe_cast_indexer(key))
  File "pandas/_libs/index.pyx", line 140, in pandas._libs.index.IndexEngine.get_loc
  File "pandas/_libs/index.pyx", line 162, in pandas._libs.index.IndexEngine.get_loc
  File "pandas/_libs/hashtable_class_helper.pxi", line 1492, in pandas._libs.hashtable.PyObjectHashTable.get_item
  File "pandas/_libs/hashtable_class_helper.pxi", line 1500, in pandas._libs.hashtable.PyObjectHashTable.get_item
KeyError: 'Avg Power'
2020-05-10 04:09:51,577 - __main__ - ERROR - time data '2020-04-07 18:15:58' does not match format '%d-%m-%y %H:%M'
Traceback (most recent call last):
  File "/Users/qiutingli/Projects/monitoring-athletes-performance/main/data_summary.py", line 41, in summarize_dates
    dates = [datetime.datetime.strptime(date, "%d-%m-%y %H:%M") for date in df['Date']]
  File "/Users/qiutingli/Projects/monitoring-athletes-performance/main/data_summary.py", line 41, in <listcomp>
    dates = [datetime.datetime.strptime(date, "%d-%m-%y %H:%M") for date in df['Date']]
  File "/Users/qiutingli/anaconda3/lib/python3.6/_strptime.py", line 565, in _strptime_datetime
    tt, fraction = _strptime(data_string, format)
  File "/Users/qiutingli/anaconda3/lib/python3.6/_strptime.py", line 362, in _strptime
    (data_string, format))
ValueError: time data '2020-04-07 18:15:58' does not match format '%d-%m-%y %H:%M'
2020-05-10 04:09:51,581 - __main__ - ERROR - could not convert string to float: '14,0'
Traceback (most recent call last):
  File "/Users/qiutingli/Projects/monitoring-athletes-performance/main/data_summary.py", line 56, in summarize_workout_time
    total_seconds = total_seconds*60 + float(t)
ValueError: could not convert string to float: '14,0'
2020-05-10 04:09:51,583 - __main__ - ERROR - 'Avg Power'
Traceback (most recent call last):
  File "/Users/qiutingli/anaconda3/lib/python3.6/site-packages/pandas/core/indexes/base.py", line 3063, in get_loc
    return self._engine.get_loc(key)
  File "pandas/_libs/index.pyx", line 140, in pandas._libs.index.IndexEngine.get_loc
  File "pandas/_libs/index.pyx", line 162, in pandas._libs.index.IndexEngine.get_loc
  File "pandas/_libs/hashtable_class_helper.pxi", line 1492, in pandas._libs.hashtable.PyObjectHashTable.get_item
  File "pandas/_libs/hashtable_class_helper.pxi", line 1500, in pandas._libs.hashtable.PyObjectHashTable.get_item
KeyError: 'Avg Power'

During handling of the above exception, another exception occurred:

Traceback (most recent call last):
  File "/Users/qiutingli/Projects/monitoring-athletes-performance/main/data_summary.py", line 83, in summarize_features
    feature_values = [float(str(var).replace(',', '')) for var in df[feature] if re.match(r'^-?\d+(?:\.\d+)?$', str(var)) is not None]
  File "/Users/qiutingli/anaconda3/lib/python3.6/site-packages/pandas/core/frame.py", line 2685, in __getitem__
    return self._getitem_column(key)
  File "/Users/qiutingli/anaconda3/lib/python3.6/site-packages/pandas/core/frame.py", line 2692, in _getitem_column
    return self._get_item_cache(key)
  File "/Users/qiutingli/anaconda3/lib/python3.6/site-packages/pandas/core/generic.py", line 2486, in _get_item_cache
    values = self._data.get(item)
  File "/Users/qiutingli/anaconda3/lib/python3.6/site-packages/pandas/core/internals.py", line 4115, in get
    loc = self.items.get_loc(item)
  File "/Users/qiutingli/anaconda3/lib/python3.6/site-packages/pandas/core/indexes/base.py", line 3065, in get_loc
    return self._engine.get_loc(self._maybe_cast_indexer(key))
  File "pandas/_libs/index.pyx", line 140, in pandas._libs.index.IndexEngine.get_loc
  File "pandas/_libs/index.pyx", line 162, in pandas._libs.index.IndexEngine.get_loc
  File "pandas/_libs/hashtable_class_helper.pxi", line 1492, in pandas._libs.hashtable.PyObjectHashTable.get_item
  File "pandas/_libs/hashtable_class_helper.pxi", line 1500, in pandas._libs.hashtable.PyObjectHashTable.get_item
KeyError: 'Avg Power'
2020-05-10 04:09:51,623 - __main__ - ERROR - time data '22/02/2020 8:15' does not match format '%d-%m-%y %H:%M'
Traceback (most recent call last):
  File "/Users/qiutingli/Projects/monitoring-athletes-performance/main/data_summary.py", line 41, in summarize_dates
    dates = [datetime.datetime.strptime(date, "%d-%m-%y %H:%M") for date in df['Date']]
  File "/Users/qiutingli/Projects/monitoring-athletes-performance/main/data_summary.py", line 41, in <listcomp>
    dates = [datetime.datetime.strptime(date, "%d-%m-%y %H:%M") for date in df['Date']]
  File "/Users/qiutingli/anaconda3/lib/python3.6/_strptime.py", line 565, in _strptime_datetime
    tt, fraction = _strptime(data_string, format)
  File "/Users/qiutingli/anaconda3/lib/python3.6/_strptime.py", line 362, in _strptime
    (data_string, format))
ValueError: time data '22/02/2020 8:15' does not match format '%d-%m-%y %H:%M'
2020-05-10 04:09:51,627 - __main__ - ERROR - time data '29/02/2020 6:26' does not match format '%d-%m-%y %H:%M'
Traceback (most recent call last):
  File "/Users/qiutingli/Projects/monitoring-athletes-performance/main/data_summary.py", line 41, in summarize_dates
    dates = [datetime.datetime.strptime(date, "%d-%m-%y %H:%M") for date in df['Date']]
  File "/Users/qiutingli/Projects/monitoring-athletes-performance/main/data_summary.py", line 41, in <listcomp>
    dates = [datetime.datetime.strptime(date, "%d-%m-%y %H:%M") for date in df['Date']]
  File "/Users/qiutingli/anaconda3/lib/python3.6/_strptime.py", line 565, in _strptime_datetime
    tt, fraction = _strptime(data_string, format)
  File "/Users/qiutingli/anaconda3/lib/python3.6/_strptime.py", line 362, in _strptime
    (data_string, format))
ValueError: time data '29/02/2020 6:26' does not match format '%d-%m-%y %H:%M'
2020-05-10 04:09:51,631 - __main__ - ERROR - time data '28/02/2020 5:46' does not match format '%d-%m-%y %H:%M'
Traceback (most recent call last):
  File "/Users/qiutingli/Projects/monitoring-athletes-performance/main/data_summary.py", line 41, in summarize_dates
    dates = [datetime.datetime.strptime(date, "%d-%m-%y %H:%M") for date in df['Date']]
  File "/Users/qiutingli/Projects/monitoring-athletes-performance/main/data_summary.py", line 41, in <listcomp>
    dates = [datetime.datetime.strptime(date, "%d-%m-%y %H:%M") for date in df['Date']]
  File "/Users/qiutingli/anaconda3/lib/python3.6/_strptime.py", line 565, in _strptime_datetime
    tt, fraction = _strptime(data_string, format)
  File "/Users/qiutingli/anaconda3/lib/python3.6/_strptime.py", line 362, in _strptime
    (data_string, format))
ValueError: time data '28/02/2020 5:46' does not match format '%d-%m-%y %H:%M'
2020-05-10 04:09:51,635 - __main__ - ERROR - time data '26/02/2020 19:15' does not match format '%d-%m-%y %H:%M'
Traceback (most recent call last):
  File "/Users/qiutingli/Projects/monitoring-athletes-performance/main/data_summary.py", line 41, in summarize_dates
    dates = [datetime.datetime.strptime(date, "%d-%m-%y %H:%M") for date in df['Date']]
  File "/Users/qiutingli/Projects/monitoring-athletes-performance/main/data_summary.py", line 41, in <listcomp>
    dates = [datetime.datetime.strptime(date, "%d-%m-%y %H:%M") for date in df['Date']]
  File "/Users/qiutingli/anaconda3/lib/python3.6/_strptime.py", line 565, in _strptime_datetime
    tt, fraction = _strptime(data_string, format)
  File "/Users/qiutingli/anaconda3/lib/python3.6/_strptime.py", line 362, in _strptime
    (data_string, format))
ValueError: time data '26/02/2020 19:15' does not match format '%d-%m-%y %H:%M'
2020-05-10 04:09:51,659 - __main__ - ERROR - 'Avg Speed'
Traceback (most recent call last):
  File "/Users/qiutingli/anaconda3/lib/python3.6/site-packages/pandas/core/indexes/base.py", line 3063, in get_loc
    return self._engine.get_loc(key)
  File "pandas/_libs/index.pyx", line 140, in pandas._libs.index.IndexEngine.get_loc
  File "pandas/_libs/index.pyx", line 162, in pandas._libs.index.IndexEngine.get_loc
  File "pandas/_libs/hashtable_class_helper.pxi", line 1492, in pandas._libs.hashtable.PyObjectHashTable.get_item
  File "pandas/_libs/hashtable_class_helper.pxi", line 1500, in pandas._libs.hashtable.PyObjectHashTable.get_item
KeyError: 'Avg Speed'

During handling of the above exception, another exception occurred:

Traceback (most recent call last):
  File "/Users/qiutingli/Projects/monitoring-athletes-performance/main/data_summary.py", line 83, in summarize_features
    feature_values = [float(str(var).replace(',', '')) for var in df[feature] if re.match(r'^-?\d+(?:\.\d+)?$', str(var)) is not None]
  File "/Users/qiutingli/anaconda3/lib/python3.6/site-packages/pandas/core/frame.py", line 2685, in __getitem__
    return self._getitem_column(key)
  File "/Users/qiutingli/anaconda3/lib/python3.6/site-packages/pandas/core/frame.py", line 2692, in _getitem_column
    return self._get_item_cache(key)
  File "/Users/qiutingli/anaconda3/lib/python3.6/site-packages/pandas/core/generic.py", line 2486, in _get_item_cache
    values = self._data.get(item)
  File "/Users/qiutingli/anaconda3/lib/python3.6/site-packages/pandas/core/internals.py", line 4115, in get
    loc = self.items.get_loc(item)
  File "/Users/qiutingli/anaconda3/lib/python3.6/site-packages/pandas/core/indexes/base.py", line 3065, in get_loc
    return self._engine.get_loc(self._maybe_cast_indexer(key))
  File "pandas/_libs/index.pyx", line 140, in pandas._libs.index.IndexEngine.get_loc
  File "pandas/_libs/index.pyx", line 162, in pandas._libs.index.IndexEngine.get_loc
  File "pandas/_libs/hashtable_class_helper.pxi", line 1492, in pandas._libs.hashtable.PyObjectHashTable.get_item
  File "pandas/_libs/hashtable_class_helper.pxi", line 1500, in pandas._libs.hashtable.PyObjectHashTable.get_item
KeyError: 'Avg Speed'
2020-05-10 04:09:51,663 - __main__ - ERROR - 'Avg Speed'
Traceback (most recent call last):
  File "/Users/qiutingli/anaconda3/lib/python3.6/site-packages/pandas/core/indexes/base.py", line 3063, in get_loc
    return self._engine.get_loc(key)
  File "pandas/_libs/index.pyx", line 140, in pandas._libs.index.IndexEngine.get_loc
  File "pandas/_libs/index.pyx", line 162, in pandas._libs.index.IndexEngine.get_loc
  File "pandas/_libs/hashtable_class_helper.pxi", line 1492, in pandas._libs.hashtable.PyObjectHashTable.get_item
  File "pandas/_libs/hashtable_class_helper.pxi", line 1500, in pandas._libs.hashtable.PyObjectHashTable.get_item
KeyError: 'Avg Speed'

During handling of the above exception, another exception occurred:

Traceback (most recent call last):
  File "/Users/qiutingli/Projects/monitoring-athletes-performance/main/data_summary.py", line 83, in summarize_features
    feature_values = [float(str(var).replace(',', '')) for var in df[feature] if re.match(r'^-?\d+(?:\.\d+)?$', str(var)) is not None]
  File "/Users/qiutingli/anaconda3/lib/python3.6/site-packages/pandas/core/frame.py", line 2685, in __getitem__
    return self._getitem_column(key)
  File "/Users/qiutingli/anaconda3/lib/python3.6/site-packages/pandas/core/frame.py", line 2692, in _getitem_column
    return self._get_item_cache(key)
  File "/Users/qiutingli/anaconda3/lib/python3.6/site-packages/pandas/core/generic.py", line 2486, in _get_item_cache
    values = self._data.get(item)
  File "/Users/qiutingli/anaconda3/lib/python3.6/site-packages/pandas/core/internals.py", line 4115, in get
    loc = self.items.get_loc(item)
  File "/Users/qiutingli/anaconda3/lib/python3.6/site-packages/pandas/core/indexes/base.py", line 3065, in get_loc
    return self._engine.get_loc(self._maybe_cast_indexer(key))
  File "pandas/_libs/index.pyx", line 140, in pandas._libs.index.IndexEngine.get_loc
  File "pandas/_libs/index.pyx", line 162, in pandas._libs.index.IndexEngine.get_loc
  File "pandas/_libs/hashtable_class_helper.pxi", line 1492, in pandas._libs.hashtable.PyObjectHashTable.get_item
  File "pandas/_libs/hashtable_class_helper.pxi", line 1500, in pandas._libs.hashtable.PyObjectHashTable.get_item
KeyError: 'Avg Speed'
2020-05-10 04:09:51,667 - __main__ - ERROR - 'Avg Speed'
Traceback (most recent call last):
  File "/Users/qiutingli/anaconda3/lib/python3.6/site-packages/pandas/core/indexes/base.py", line 3063, in get_loc
    return self._engine.get_loc(key)
  File "pandas/_libs/index.pyx", line 140, in pandas._libs.index.IndexEngine.get_loc
  File "pandas/_libs/index.pyx", line 162, in pandas._libs.index.IndexEngine.get_loc
  File "pandas/_libs/hashtable_class_helper.pxi", line 1492, in pandas._libs.hashtable.PyObjectHashTable.get_item
  File "pandas/_libs/hashtable_class_helper.pxi", line 1500, in pandas._libs.hashtable.PyObjectHashTable.get_item
KeyError: 'Avg Speed'

During handling of the above exception, another exception occurred:

Traceback (most recent call last):
  File "/Users/qiutingli/Projects/monitoring-athletes-performance/main/data_summary.py", line 83, in summarize_features
    feature_values = [float(str(var).replace(',', '')) for var in df[feature] if re.match(r'^-?\d+(?:\.\d+)?$', str(var)) is not None]
  File "/Users/qiutingli/anaconda3/lib/python3.6/site-packages/pandas/core/frame.py", line 2685, in __getitem__
    return self._getitem_column(key)
  File "/Users/qiutingli/anaconda3/lib/python3.6/site-packages/pandas/core/frame.py", line 2692, in _getitem_column
    return self._get_item_cache(key)
  File "/Users/qiutingli/anaconda3/lib/python3.6/site-packages/pandas/core/generic.py", line 2486, in _get_item_cache
    values = self._data.get(item)
  File "/Users/qiutingli/anaconda3/lib/python3.6/site-packages/pandas/core/internals.py", line 4115, in get
    loc = self.items.get_loc(item)
  File "/Users/qiutingli/anaconda3/lib/python3.6/site-packages/pandas/core/indexes/base.py", line 3065, in get_loc
    return self._engine.get_loc(self._maybe_cast_indexer(key))
  File "pandas/_libs/index.pyx", line 140, in pandas._libs.index.IndexEngine.get_loc
  File "pandas/_libs/index.pyx", line 162, in pandas._libs.index.IndexEngine.get_loc
  File "pandas/_libs/hashtable_class_helper.pxi", line 1492, in pandas._libs.hashtable.PyObjectHashTable.get_item
  File "pandas/_libs/hashtable_class_helper.pxi", line 1500, in pandas._libs.hashtable.PyObjectHashTable.get_item
KeyError: 'Avg Speed'
2020-05-10 04:09:51,670 - __main__ - ERROR - 'Avg Speed'
Traceback (most recent call last):
  File "/Users/qiutingli/anaconda3/lib/python3.6/site-packages/pandas/core/indexes/base.py", line 3063, in get_loc
    return self._engine.get_loc(key)
  File "pandas/_libs/index.pyx", line 140, in pandas._libs.index.IndexEngine.get_loc
  File "pandas/_libs/index.pyx", line 162, in pandas._libs.index.IndexEngine.get_loc
  File "pandas/_libs/hashtable_class_helper.pxi", line 1492, in pandas._libs.hashtable.PyObjectHashTable.get_item
  File "pandas/_libs/hashtable_class_helper.pxi", line 1500, in pandas._libs.hashtable.PyObjectHashTable.get_item
KeyError: 'Avg Speed'

During handling of the above exception, another exception occurred:

Traceback (most recent call last):
  File "/Users/qiutingli/Projects/monitoring-athletes-performance/main/data_summary.py", line 83, in summarize_features
    feature_values = [float(str(var).replace(',', '')) for var in df[feature] if re.match(r'^-?\d+(?:\.\d+)?$', str(var)) is not None]
  File "/Users/qiutingli/anaconda3/lib/python3.6/site-packages/pandas/core/frame.py", line 2685, in __getitem__
    return self._getitem_column(key)
  File "/Users/qiutingli/anaconda3/lib/python3.6/site-packages/pandas/core/frame.py", line 2692, in _getitem_column
    return self._get_item_cache(key)
  File "/Users/qiutingli/anaconda3/lib/python3.6/site-packages/pandas/core/generic.py", line 2486, in _get_item_cache
    values = self._data.get(item)
  File "/Users/qiutingli/anaconda3/lib/python3.6/site-packages/pandas/core/internals.py", line 4115, in get
    loc = self.items.get_loc(item)
  File "/Users/qiutingli/anaconda3/lib/python3.6/site-packages/pandas/core/indexes/base.py", line 3065, in get_loc
    return self._engine.get_loc(self._maybe_cast_indexer(key))
  File "pandas/_libs/index.pyx", line 140, in pandas._libs.index.IndexEngine.get_loc
  File "pandas/_libs/index.pyx", line 162, in pandas._libs.index.IndexEngine.get_loc
  File "pandas/_libs/hashtable_class_helper.pxi", line 1492, in pandas._libs.hashtable.PyObjectHashTable.get_item
  File "pandas/_libs/hashtable_class_helper.pxi", line 1500, in pandas._libs.hashtable.PyObjectHashTable.get_item
KeyError: 'Avg Speed'
2020-05-10 04:09:51,785 - __main__ - ERROR - time data '27/02/2020 18:45' does not match format '%d-%m-%y %H:%M'
Traceback (most recent call last):
  File "/Users/qiutingli/Projects/monitoring-athletes-performance/main/data_summary.py", line 41, in summarize_dates
    dates = [datetime.datetime.strptime(date, "%d-%m-%y %H:%M") for date in df['Date']]
  File "/Users/qiutingli/Projects/monitoring-athletes-performance/main/data_summary.py", line 41, in <listcomp>
    dates = [datetime.datetime.strptime(date, "%d-%m-%y %H:%M") for date in df['Date']]
  File "/Users/qiutingli/anaconda3/lib/python3.6/_strptime.py", line 565, in _strptime_datetime
    tt, fraction = _strptime(data_string, format)
  File "/Users/qiutingli/anaconda3/lib/python3.6/_strptime.py", line 362, in _strptime
    (data_string, format))
ValueError: time data '27/02/2020 18:45' does not match format '%d-%m-%y %H:%M'
2020-05-10 04:09:51,792 - __main__ - ERROR - time data '20/03/2020 5:48' does not match format '%d-%m-%y %H:%M'
Traceback (most recent call last):
  File "/Users/qiutingli/Projects/monitoring-athletes-performance/main/data_summary.py", line 41, in summarize_dates
    dates = [datetime.datetime.strptime(date, "%d-%m-%y %H:%M") for date in df['Date']]
  File "/Users/qiutingli/Projects/monitoring-athletes-performance/main/data_summary.py", line 41, in <listcomp>
    dates = [datetime.datetime.strptime(date, "%d-%m-%y %H:%M") for date in df['Date']]
  File "/Users/qiutingli/anaconda3/lib/python3.6/_strptime.py", line 565, in _strptime_datetime
    tt, fraction = _strptime(data_string, format)
  File "/Users/qiutingli/anaconda3/lib/python3.6/_strptime.py", line 362, in _strptime
    (data_string, format))
ValueError: time data '20/03/2020 5:48' does not match format '%d-%m-%y %H:%M'
2020-05-10 04:09:51,795 - __main__ - ERROR - could not convert string to float: '--'
Traceback (most recent call last):
  File "/Users/qiutingli/Projects/monitoring-athletes-performance/main/data_summary.py", line 70, in summarize_distances
    distances = [float(distance.replace(',','')) for distance in df['Distance']]
  File "/Users/qiutingli/Projects/monitoring-athletes-performance/main/data_summary.py", line 70, in <listcomp>
    distances = [float(distance.replace(',','')) for distance in df['Distance']]
ValueError: could not convert string to float: '--'
2020-05-10 04:09:51,798 - __main__ - ERROR - time data '27/03/2020 6:00' does not match format '%d-%m-%y %H:%M'
Traceback (most recent call last):
  File "/Users/qiutingli/Projects/monitoring-athletes-performance/main/data_summary.py", line 41, in summarize_dates
    dates = [datetime.datetime.strptime(date, "%d-%m-%y %H:%M") for date in df['Date']]
  File "/Users/qiutingli/Projects/monitoring-athletes-performance/main/data_summary.py", line 41, in <listcomp>
    dates = [datetime.datetime.strptime(date, "%d-%m-%y %H:%M") for date in df['Date']]
  File "/Users/qiutingli/anaconda3/lib/python3.6/_strptime.py", line 565, in _strptime_datetime
    tt, fraction = _strptime(data_string, format)
  File "/Users/qiutingli/anaconda3/lib/python3.6/_strptime.py", line 362, in _strptime
    (data_string, format))
ValueError: time data '27/03/2020 6:00' does not match format '%d-%m-%y %H:%M'
2020-05-10 04:09:51,804 - __main__ - ERROR - time data '3/09/2019 18:23' does not match format '%d-%m-%y %H:%M'
Traceback (most recent call last):
  File "/Users/qiutingli/Projects/monitoring-athletes-performance/main/data_summary.py", line 41, in summarize_dates
    dates = [datetime.datetime.strptime(date, "%d-%m-%y %H:%M") for date in df['Date']]
  File "/Users/qiutingli/Projects/monitoring-athletes-performance/main/data_summary.py", line 41, in <listcomp>
    dates = [datetime.datetime.strptime(date, "%d-%m-%y %H:%M") for date in df['Date']]
  File "/Users/qiutingli/anaconda3/lib/python3.6/_strptime.py", line 565, in _strptime_datetime
    tt, fraction = _strptime(data_string, format)
  File "/Users/qiutingli/anaconda3/lib/python3.6/_strptime.py", line 362, in _strptime
    (data_string, format))
ValueError: time data '3/09/2019 18:23' does not match format '%d-%m-%y %H:%M'
2020-05-10 04:09:51,944 - __main__ - ERROR - time data '2020-04-12 13:19:55' does not match format '%d-%m-%y %H:%M'
Traceback (most recent call last):
  File "/Users/qiutingli/Projects/monitoring-athletes-performance/main/data_summary.py", line 41, in summarize_dates
    dates = [datetime.datetime.strptime(date, "%d-%m-%y %H:%M") for date in df['Date']]
  File "/Users/qiutingli/Projects/monitoring-athletes-performance/main/data_summary.py", line 41, in <listcomp>
    dates = [datetime.datetime.strptime(date, "%d-%m-%y %H:%M") for date in df['Date']]
  File "/Users/qiutingli/anaconda3/lib/python3.6/_strptime.py", line 565, in _strptime_datetime
    tt, fraction = _strptime(data_string, format)
  File "/Users/qiutingli/anaconda3/lib/python3.6/_strptime.py", line 362, in _strptime
    (data_string, format))
ValueError: time data '2020-04-12 13:19:55' does not match format '%d-%m-%y %H:%M'
2020-05-10 04:09:51,953 - __main__ - ERROR - time data '2020-03-26 08:08:14' does not match format '%d-%m-%y %H:%M'
Traceback (most recent call last):
  File "/Users/qiutingli/Projects/monitoring-athletes-performance/main/data_summary.py", line 41, in summarize_dates
    dates = [datetime.datetime.strptime(date, "%d-%m-%y %H:%M") for date in df['Date']]
  File "/Users/qiutingli/Projects/monitoring-athletes-performance/main/data_summary.py", line 41, in <listcomp>
    dates = [datetime.datetime.strptime(date, "%d-%m-%y %H:%M") for date in df['Date']]
  File "/Users/qiutingli/anaconda3/lib/python3.6/_strptime.py", line 565, in _strptime_datetime
    tt, fraction = _strptime(data_string, format)
  File "/Users/qiutingli/anaconda3/lib/python3.6/_strptime.py", line 362, in _strptime
    (data_string, format))
ValueError: time data '2020-03-26 08:08:14' does not match format '%d-%m-%y %H:%M'
2020-05-10 04:09:51,959 - __main__ - ERROR - time data '2020-03-20 05:47:13' does not match format '%d-%m-%y %H:%M'
Traceback (most recent call last):
  File "/Users/qiutingli/Projects/monitoring-athletes-performance/main/data_summary.py", line 41, in summarize_dates
    dates = [datetime.datetime.strptime(date, "%d-%m-%y %H:%M") for date in df['Date']]
  File "/Users/qiutingli/Projects/monitoring-athletes-performance/main/data_summary.py", line 41, in <listcomp>
    dates = [datetime.datetime.strptime(date, "%d-%m-%y %H:%M") for date in df['Date']]
  File "/Users/qiutingli/anaconda3/lib/python3.6/_strptime.py", line 565, in _strptime_datetime
    tt, fraction = _strptime(data_string, format)
  File "/Users/qiutingli/anaconda3/lib/python3.6/_strptime.py", line 362, in _strptime
    (data_string, format))
ValueError: time data '2020-03-20 05:47:13' does not match format '%d-%m-%y %H:%M'
2020-05-10 04:09:51,964 - __main__ - ERROR - time data '2020-04-14 16:57:53' does not match format '%d-%m-%y %H:%M'
Traceback (most recent call last):
  File "/Users/qiutingli/Projects/monitoring-athletes-performance/main/data_summary.py", line 41, in summarize_dates
    dates = [datetime.datetime.strptime(date, "%d-%m-%y %H:%M") for date in df['Date']]
  File "/Users/qiutingli/Projects/monitoring-athletes-performance/main/data_summary.py", line 41, in <listcomp>
    dates = [datetime.datetime.strptime(date, "%d-%m-%y %H:%M") for date in df['Date']]
  File "/Users/qiutingli/anaconda3/lib/python3.6/_strptime.py", line 565, in _strptime_datetime
    tt, fraction = _strptime(data_string, format)
  File "/Users/qiutingli/anaconda3/lib/python3.6/_strptime.py", line 362, in _strptime
    (data_string, format))
ValueError: time data '2020-04-14 16:57:53' does not match format '%d-%m-%y %H:%M'

